
---
*üìÖ **created: 28-08-2025 / 12:48**
üè∑Ô∏è **tags: []**
**‚åõ status: draft**
## üìã Resumo

> Breve descri√ß√£o do conte√∫do

## üìö [[CSharpIniciantes.pdf#page=127&selection=0,14,0,35&color=yellow|Tratamento de Exce√ß√µes]]

Uma exce√ß√£o √© um erro causado por alguma opera√ß√£o dentro do software, como por exemplo, falha em ler um arquivo do disco, falha em se conectar a um banco de dados, uma vari√°vel sem um valor adequado, entre muitos outros.  importante neste caso √© tratarmos o erro de maneira que o usu√°rio da aplica√ß√£o receba alguma informa√ß√£o que fa√ßa sentido para ele.

Outro aspecto no tratamento de exce√ß√µes √© relativo √° seguran√ßa da aplica√ß√£o, pois se deixarmos um erro aparecer "em sua forma bruta" para o usu√°rio, podemos estar expondo dados sens√≠veis da nossa aplica√ß√£o, como banco de dados que usamos, tecnologia, linguagem, al√©m de outros dados que podem ser utilizados sem o nosso conhecimento.

Para entendermos os erros e como trata-los de maneira correta, iremos explorar o mecanismo de tratamento de exce√ß√µes da linguagem C#.
### O que √© um erro ?

Um erro √© um comportamento que pode paralisar nossa aplica√ß√£o, seu fluxo normal de execu√ß√£o, ent√£o, quando um erro acontece, podemos chama-lo de "exce√ß√£o", pois √© algo que n√£o planejamos , e claro, n√£o planejamos erros em nossa aplica√ß√£o, mas precisamos planejar o que fazer como eles caso aconte√ßam.

Alguns exemplos comuns de erros:

-  Banco de dados indispon√≠vel: por algum erro de rede ou alto n√≠vel de                  processamento, nossa aplica√ß√£o n√£o consegue acessar o banco de dados.
-  Dados Nulos: chamamos uma fun√ß√£o externa e o valor retornado √© um nulo e    n√£o  o que deveria voltar de fato.
-  Erros Matem√°ticos: um erro bem comum nesta √°rea √© o erro e divis√£o por zero.

E assim podemos listar aqui centenas de tipos de erros que podem acontecer na aplica√ß√£o.
### Sempre teremos erro em nossa aplica√ß√£o?

N√≥s n√£o criamos uma aplica√ß√£o para ela conter erros, mas eles podem acontecer, e como um bom desenvolvedor, precisamos tratar esses erros, evitando problemas maiores na aplica√ß√£o. Al√©m disso, existem recursos que consumimos em uma aplica√ß√£o que est√£o fora o nosso controle, por exemplo, dados acessados pela internet, um servi√ßo de banco de dados externo, uma API, ou seja, temos muitos pontos em uma aplica√ß√£o que realmente podem falhar e nossa miss√£o √© tratar tudo isto da melhor maneira poss√≠vel.

### Como tratamos um erro?

J√° entendemos que erros podem acontecer e que precisamos trat√°-los, o que precisamos agora √© saber a melhor maneira de fazer isto e principalmente, identificar pontos de falha em nosso c√≥digo que possam gerar um problema.

Para iniciarmos com os estudos de tratamento de erros, vamos acompanhar o c√≥digo a seguir que se trata de uma divis√£o de dois n√∫meros.

```csharp
namespace Modulo_5
{
     class ProgramaPrincipal
    {
        static void Main(string[] args)
        {
            TratamentoExcecao tratamentoExcecao = new TratamentoExcecao();
            tratamentoExcecao.ExemploTratamentoExcecao();
        }
    }
    public class TratamentoExcecao
    {
        public void ExemploTratamentoExcecao()
        {
            Console.WriteLine("Divis√£o de dois n√∫meros");
            Console.WriteLine();
            Console.Write("Digite o Primeiro n√∫mero: ");
            var strNum1 = Console.ReadLine();
            Console.Write("Digite o Segundo n√∫mero: ");
            var strNum2 = Console.ReadLine();
            int num1 = int.Parse(strNum1);
            int num2 = int.Parse(strNum2);
            var divisao = num1 / num2;
            Console.WriteLine($"A divis√£o de {num1} por {num2} √© {divisao}");
            Console.WriteLine("FIM");
        }
    }
}
```

Vamos entender o c√≥digo: Pegamos o primeiro e o segundo n√∫mero e guardamos em duas vari√°veis chamadas de num1 e num2. Como a fun√ß√£o Console.ReadKey() retorna apenas uma string, precisamos converter num1 e num2 para int, ent√£o usamos a fun√ß√£o int.Parse() que converte uma string para um int. Finalmente pegamos os dois valores e agora como inteiros e fazemos a divis√£o.

Primeiro vamos fazer o que chamamos de "caminho feliz", ou seja, vamos usar a nossa aplica√ß√£o como ela foi criada, informando os valores corretamente: 

```
Resultado:
Divis√£o de dois n√∫meros

Digite o Primeiro n√∫mero: 10
Digite o Segundo n√∫mero: 2
A divis√£o de 10 por 2 √© 5
FIM
```

A pergunta aqui √© o que poderia dar errado neste c√≥digo t√£o simples? E a resposta √©: muitas coisas, vamos l√°: o usu√°rio n√£o digitou nada no campo dos n√∫meros, o que provoca um erro na convers√£o para int. Isso resulta nesta mensagem de erro:

```
Divis√£o de dois n√∫meros

Digite o Primeiro n√∫mero:
Digite o Segundo n√∫mero:
Unhandled exception. System.FormatException: The input string '' was not in a correct format.
   at System.Number.ThrowFormatException[TChar](ReadOnlySpan`1 value)
   at System.Int32.Parse(String s)
   at Modulo_5.TratamentoExcecao.ExemploTratamentoExcecao() in B:\Knolage_Base\Codigos\CsharpParaInciantes\Modulo 5\Program.cs:line 21
   at Modulo_5.ProgramaPrincipal.Main(String[] args) in B:\Knolage_Base\Codigos\CsharpParaInciantes\Modulo 5\Program.cs:line 8
```

Agora o usu√°rio digita um valor inv√°lido no campo:

```
Divis√£o de dois n√∫meros

Digite o Primeiro n√∫mero: 0
Digite o Segundo n√∫mero: 0
Unhandled exception. System.DivideByZeroException: Attempted to divide by zero.
   at Modulo_5.TratamentoExcecao.ExemploTratamentoExcecao() in B:\Knolage_Base\Codigos\CsharpParaInciantes\Modulo 5\Program.cs:line 23
   at Modulo_5.ProgramaPrincipal.Main(String[] args) in B:\Knolage_Base\Codigos\CsharpParaInciantes\Modulo 5\Program.cs:line 8
```

Em nenhum dos dois exemplos, a palavra "FIM" foi impressa na tela, pois ela estava depois da conta de dividir, onde o erro foi provocado, Ent√£o o erro interrompeu o fluxo da nossa aplica√ß√£o. O que precisamos fazer √© tratar o erro e seguir com a execu√ß√£o da aplica√ß√£o, ent√£o vamos incluir no nosso exemplo um tratamento de exce√ß√£o:

```csharp
namespace Modulo_5
{
     class ProgramaPrincipal
    {
        static void Main(string[] args)
        {
            TratamentoExcecao tratamentoExcecao = new TratamentoExcecao();
            tratamentoExcecao.ExemploTratamentoExcecao();
        }
    }
    public class TratamentoExcecao
    {
        public void ExemploTratamentoExcecao()
        {
            Console.WriteLine("Divis√£o de dois n√∫meros");
            Console.WriteLine();
            Console.Write("Digite o Primeiro n√∫mero: ");
            var strNum1 = Console.ReadLine();
            Console.Write("Digite o Segundo n√∫mero: ");
            var strNum2 = Console.ReadLine();
            try
            {
                int num1 = int.Parse(strNum1);
                int num2 = int.Parse(strNum2);
                var divisao = num1 / num2;
                Console.WriteLine($"A divis√£o de {num1} por {num2} √© {divisao}");
            }
            catch (Exception ex)
            {
                Console.WriteLine($"Erro na divis√£o:{ex.Message}");
            }
            Console.WriteLine("FIM");
        }
    }
}
```

Quem resolve o problema do tratamento de exce√ß√£o no C# √© o bloco try...catch...finaly. Este bloco √© o respons√°vel por tratar qualquer exce√ß√£o que ocorra dentro do try, pegando o erro no catch, e em alguns casos, excetuando c√≥digo no finally.

Ent√£o o c√≥digo que queremos proteger fica dentro do bloco try, que no nosso exemplo √© a convers√£o do dado e a divis√£o. Se acontecer algum erro dentro do try, ent√£o o bloco catch √© chamado, e no nosso caso, mostramos uma mensagem que recebemos de erro. O nosso exemplo n√£o tem finally, mas iremos explorar este bloco depois. Vejamos como ficou o resultado no caso do usu√°rio n√£o ter passado nenhum valor:

```
Divis√£o de dois n√∫meros

Digite o Primeiro n√∫mero:
Digite o Segundo n√∫mero:
Erro na divis√£o:The input string '' was not in a correct format.
FIM
```

E agora em caso de divis√£o por zero:

```
Divis√£o de dois n√∫meros

Digite o Primeiro n√∫mero: 0
Digite o Segundo n√∫mero: 0
Erro na divis√£o:Attempted to divide by zero.
FIM
```

Agora temos uma mensagem de erro mais simples e tamb√©m temos a palavra "FIM" sendo mostrada nos dois casos.

O bloco try...catch...finally √© muito √∫til mas n√£o deve ser utilizado em toda a nossa aplica√ß√£o, ou seja, n√£o comecemos o c√≥digo com um try, coloquemos o bloco onde realmente precisemos. E isto s√≥ iremos aprender com o uso da linguagem e a constru√ß√£o de aplica√ß√µes, Mas vamos ver um exemplo de como n√£o usar um bloco try:

```csharp
try
{
    int a = 1;
    int b = 0;
    int c = a / b;
}
catch
{

}
```

Este c√≥digo provoca um erro que pode nunca ser encontrado, pois o catch n√£o mostra nada, absolutamente nada; Se n√£o temos certeza do que escrever no catch, usamos o comando throw:

```csharp
try
{
    int a = 1;
    int b = 0;
    int c = a / b;
}
catch
{
	throw;
}
```

O throw joga a exce√ß√£o para quem chamou o c√≥digo.
### Tratando erros espec√≠ficos com try...catch

Vimos como tratar um erro dentro no nosso c√≥digo C#, mas at√© agora estamos tratando este erro de maneira gen√©rica, atrav√©s da classe Exception, mas o C# tem uma hierarquia de tratamento de erros, que vai do mais espec√≠fico para o mais gen√©rico.

Isso pode ter parecido um pouco estranho, ent√£o vamos explicar usando o c√≥digo do nosso exemplo anterior, mas incrementando o tratamento de erros:

```csharp
public class TratamentoExcecao
{
    public void ExemploTratamentoExcecao()
    {
        Console.WriteLine("Divis√£o de dois n√∫meros");
        Console.WriteLine();
        Console.Write("Digite o Primeiro n√∫mero: ");
        var strNum1 = Console.ReadLine();
        Console.Write("Digite o Segundo n√∫mero: ");
        var strNum2 = Console.ReadLine();
        try
        {
            int num1 = int.Parse(strNum1);
            int num2 = int.Parse(strNum2);
            var divisao = num1 / num2;
            Console.WriteLine($"A divis√£o de {num1} por {num2} √© {divisao}");
        }
        catch(DivideByZeroException ex)
        {
            Console.WriteLine($"Erro de divis√£o por zero: {ex.Message}");
        }
        catch(FormatException ex)
        {
            Console.WriteLine($"Erro de Formata√ß√£o: {ex.Message}");
        }
        catch (Exception ex)
        {
            Console.WriteLine($"Erro na divis√£o:{ex.Message}");
        }
        Console.WriteLine("FIM");
    }
}
```

Agora temos tr√™s blocos catch, onde o primeiro trata erro de divis√£o por zero, o segundo trata erro de formato e o ultimo trata qualquer erro que n√£o foi tratado pelos anteriores. Ent√£o √© bem simples, vamos tratar os erros do mais espec√≠fico para o mais gen√©rico.

Mas qual a vantagem disto? A vantagem √© que usando uma classe espec√≠fica podemos pegar mais detalhes dos erros. Se executarmos novamente o c√≥digo dos exemplos anteriores teremos o resultado a seguir:

```
Divis√£o de dois n√∫meros

Digite o Primeiro n√∫mero:
Digite o Segundo n√∫mero:
Erro de Formata√ß√£o: The input string '' was not in a correct format.
FIM
```

Temos a mensagem  "Erro de Formata√ß√£o" pois o erro foi provocado por um dado inserido incorretamente e que n√£o pode ser convertido.

```
Divis√£o de dois n√∫meros

Digite o Primeiro n√∫mero: 0
Digite o Segundo n√∫mero: 0
Erro de divis√£o por zero: Attempted to divide by zero.
FIM
```

E agora temos uma mensagem espec√≠fica de divis√£o por Zero.

### O comando finally

Agora que j√° entendemos o try...catch, vou adicionar o segmento finally, que sempre √© executado, independente do que ocorra no try ou no catch. Vamos ver no c√≥digo a seguir:

```csharp
public class TratamentoExcecao
{
    public void ExemploTratamentoExcecao()
    {
        Console.WriteLine("Divis√£o de dois n√∫meros");
        Console.WriteLine();
        Console.Write("Digite o Primeiro n√∫mero: ");
        var strNum1 = Console.ReadLine();
        Console.Write("Digite o Segundo n√∫mero: ");
        var strNum2 = Console.ReadLine();
        try
        {
            int num1 = int.Parse(strNum1);
            int num2 = int.Parse(strNum2);
            var divisao = num1 / num2;
            Console.WriteLine($"A divis√£o de {num1} por {num2} √© {divisao}");
        }
        catch(DivideByZeroException ex)
        {
            Console.WriteLine($"Erro de divis√£o por zero: {ex.Message}");
        }
        catch(FormatException ex)
        {
            Console.WriteLine($"Erro de Formata√ß√£o: {ex.Message}");
        }
        catch (Exception ex)
        {
            Console.WriteLine($"Erro na divis√£o:{ex.Message}");
        }
        finally
        {
            Console.WriteLine("Sempre vai excecutar o Finally");
        }
        Console.WriteLine("FIM");
    }
}
```

```
Divis√£o de dois n√∫meros

Digite o Primeiro n√∫mero: 10
Digite o Segundo n√∫mero: 5
A divis√£o de 10 por 5 √© 2
Sempre vai excecutar o Finally
FIM
```

O tratamento de erros, de maneira correta, √© extremamente importante para uma aplica√ß√£o. N√£o devemos deixar erros sem sentido na tela do usu√°rio, sempre mostrar informa√ß√µes que fazem sentido e orientem para o correto uso da aplica√ß√£o.

---



 
